Workbook

Sheet Budget - Consultation
A1: Project Budget
G2: Approved Budget Changes
C3: Project Name | G3: Reason | H3: Plan or CR ID | I3: Changes Cost | J3: Changes Revenue
C4: Client
C5: Contract start date
C6: Contract end date
C7: Contract duration
C8: Contract Type | D8: FS
C9: Scope
C10: Support start and end dates | D10: 46525 | E10: 46890
C11: Progress | D11: ='Profitability - Consultation'!Q1
B12: (1) | C12: Total Mandays | E12: =Table_6712[[#Totals],[Total No of MDs]] | G12: Total Changes on Budget | I12: =SUM(I4:I8) | J12: =SUM(J4:J8)
B14: Approved Project Budget | G14: Final Budget (SAR)
B15: (2) | C15: Total Estimated Cost ($) | E15: =Table_6712[[#Totals],[Total cost USD]] | G15: Total Cost after changes | I15: =E16+I12
B16: (3) | C16: Total Estimated Cost (SAR) | E16: ='Estimated Cost - Consultation'!D23 | G16: Total Revenue after changes | I16: =E17+J12
B17: (4) | C17: Total Revenue | E17: 6641250 | F17: 10312459 | G17: Budget Profit (SAR) | I17: =I16-I15
B18: (5) | C18: Budget Profit (SAR) | E18: =E17-E16 | G18: Budget Profit (%) | I18: =I17/I16
B19: (6) | C19: Budget Profit (%) | E19: =E18/E17
C21: Estimated MD cost (SAR) | E21: =E16/E12
C23: Estimated MD Price (SAR) | E23: =E17/E12
B25: Invoices Schedule
B26: # | C26: Invoiced Item | D26: Planned Date | E26: Invoice Value | F26: Business Line | G26: Status
B27: 1 | F27: License
B28: 2 | F28: Service
B29: 3 | F29: 3rd Party
B30: 4
B31: 5
B32: 6
B33: 7
B34: 8
B35: 9
B36: 10

Sheet Budget - Development
A1: Project Budget
G2: Approved Budget Changes
C3: Project Name | D3: Abdelrahman Doghish | G3: Reason | H3: Plan or CR ID | I3: Changes Cost | J3: Changes Revenue
C4: Client | G4: Third party license | J4: -420000
C5: Contract start date | G5: Outsystems license | J5: -3960000
C6: Contract end date
C7: Contract duration
C8: Contract Type | D8: FS
C9: Scope
C10: Support start and end dates | D10: 46525 | E10: 46890
C11: Progress | D11: ='Profitability - Consultation'!Q1
B12: (1) | C12: Total Mandays | E12: =Table_67124[[#Totals],[Total No of MDs]] | G12: Total Changes on Budget | I12: =SUM(I4:I8) | J12: =SUM(J4:J8)
B14: Approved Project Budget | G14: Final Budget (SAR)
B15: (2) | C15: Total Estimated Cost ($) | E15: =Table_67124[[#Totals],[Total cost USD]] | G15: Total Cost after changes | I15: =E16+I12
B16: (3) | C16: Total Estimated Cost (SAR) | E16: ='Estimated Cost - Development'!D33 | G16: Total Revenue after changes | I16: =E17+J12
B17: (4) | C17: Total Revenue | E17: 20570344 | G17: Budget Profit (SAR) | I17: =I16-I15
B18: (5) | C18: Budget Profit (SAR) | E18: =E17-E16 | G18: Budget Profit (%) | I18: =I17/I16
B19: (6) | C19: Budget Profit (%) | E19: =E18/E17
C21: Estimated MD cost (SAR) | E21: =E16/E12
C23: Estimated MD Price (SAR) | E23: =E17/E12
B25: Invoices Schedule
B26: # | C26: Invoiced Item | D26: Planned Date | E26: Invoice Value | F26: Business Line | G26: Status
B27: 1 | F27: License
B28: 2 | F28: Service
B29: 3 | F29: 3rd Party
B30: 4
B31: 5
B32: 6
B33: 7
B34: 8
B35: 9
B36: 10

Sheet Budget - Support
A1: Project Budget
G2: Approved Budget Changes
C3: Project Name | G3: Reason | H3: Plan or CR ID | I3: Changes Cost | J3: Changes Revenue
C4: Client
C5: Contract start date
C6: Contract end date
C7: Contract duration
C8: Contract Type | D8: FS
C9: Scope
C10: Support start and end dates | D10: 46525 | E10: 46890
C11: Progress | D11: ='Profitability - Consultation'!Q1
B12: (1) | C12: Total Mandays | E12: 528 | G12: Total Changes on Budget | I12: 0 | J12: 0
B14: Approved Project Budget | G14: Final Budget (SAR)
B15: (2) | C15: Total Estimated Cost ($) | E15: =Table_67122[[#Totals],[Total cost USD]] | G15: Total Cost after changes | I15: =E16+I12
B16: (3) | C16: Total Estimated Cost (SAR) | E16: ='Estimated Cost - Support'!D15 | G16: Total Revenue after changes | I16: =E17+J12
B17: (4) | C17: Total Revenue | E17: 2079000 | G17: Budget Profit (SAR) | I17: =I16-I15
B18: (5) | C18: Budget Profit (SAR) | E18: =E17-E16 | G18: Budget Profit (%) | I18: =I17/I16
B19: (6) | C19: Budget Profit (%) | E19: =E18/E17
C21: Estimated MD cost (SAR) | E21: =E16/E12
C23: Estimated MD Price (SAR) | E23: =E17/E12
B25: Invoices Schedule
B26: # | C26: Invoiced Item | D26: Planned Date | E26: Invoice Value | F26: Business Line | G26: Status
B27: 1 | F27: License
B28: 2 | F28: Service
B29: 3 | F29: 3rd Party
B30: 4
B31: 5
B32: 6
B33: 7
B34: 8
B35: 9
B36: 10

Sheet Profitability - Development
A1: Project Name | F1: PM Name
A2: Contract Start Date | F2: Contract End Date | J2: Current Scope
A3: Support Start Date | F3: Support End Date
A4: Licenses and 3rd party Revenue | F4: Licenses and 3rd party Cost
C5: Presales Budget | F5: Current Month calculations | P5: Cost Variance | T5: Profitability | W5: Profit Variance | Y5: Progress and Virtual Invoices for fixed cost
A6: Month | B6: Consumed Revenue | C6: Total Revenue (SAR) | D6: Total Estimated Cost (SAR) | E6: Estimated Effort MDs | F6: This month MDs | G6: Actual Effort to Date (MD) | H6: % Completion from plan | I6: Current Cost (SAR) | J6: Estimated Remaining (MD) | K6: EAC MDs | L6: Expected overrun (SAR) | M6: Revenue to date | N6: Estimated Cost to Complete | O6: Estimate at Completion | P6: CPI | Q6: Variance | R6: Variance (%) | T6: Profit at Completion | U6: Planned Profit | V6: Profit at Completion (%) | W6: Profitability Variance | X6: Profitability Variance (%) | Y6: Total Issued Invoices (SAR) | Z6: Progress % | AA6: Total Recognized Revenue | AB6: Production | AC6: Accumulative virtual invoice | AD6: This month Virtual Invoice | AE6: VI+Issued
I7: (7) | J7: (8) | N7: (9) | O7: (10) | Q7: (11) | R7: (12) | T7: (13) | V7: (14) | W7: (15) | X7: (16) | Y7: (17) | Z7: (18) | AA7: (19)
A8: 46102 | C8: 16190344 | D8: 10257885 | E8: 6556 | F8: ='Current Effort - Development'!I19 | G8: =F8 | H8: 0.01 | I8: 32032 | J8: 6556 | K8: 6529.0833 | L8: -0.58943461 | M8: 161903.44 | N8: 6746253.4 | O8: =N8+I8 | P8: =D8/O8 | Q8: =D8-O8 | R8: =Q8/C8 | T8: =C8-O8 | U8: 0.36641958 | V8: =T8/C8 | W8: =T8-'Budget - Consultation'!$I$17 | X8: =V8-'Budget - Consultation'!$I$18 | Z8: 0.0040888664 | AA8: 161903.44 | AB8: 161903.44 | AC8: 161903.44 | AD8: 161903.44 | AE8: 161903.44
A9: 46133 | C9: ='Budget - Development'!I16 | D9: ='Budget - Development'!I15 | E9: ='Budget - Development'!E12 | F9: ='Current Effort - Development'!L19 | G9: ='Current Effort - Development'!AO19 | H9: 0.03 | I9: ='Current Effort - Development'!N22 | K9: =E9-G9 | L9: =(G9/E9)/H9-100% | M9: =H9*C9 | N9: =J9*'Current Effort - Development'!N$23 | O9: =N9+I9 | P9: =D9/O9 | Q9: =D9-O9 | R9: =Q9/C9 | T9: =C9-O9 | U9: ='Budget - Development'!I18 | V9: =T9/C9 | W9: =T9-'Budget - Consultation'!$I$17 | X9: =V9-'Budget - Consultation'!$I$18 | Z9: =I9/O9 | AA9: =C9*H9 | AB9: =AA9 | AC9: =AA9-Y9 | AD9: =AC9 | AE9: =AC9+Y9

Sheet Current Effort - Development
B1: Fill in Yellow Cells with current Team Effort
G4: March | J4: April | M4: May | P4: June | S4: July | V4: August | Y4: September | AB4: October | AE4: November | AH4: December | AK4: January
A5: # | B5: Name | D5: Position | E5: Hour Rate ($) | F5: Overtime Rate | G5: Regular Time (MH) | H5: Ramdan Hours | I5: Over Time (MH) | J5: Regular Time (MH) | K5: Ramdan Hours | L5: Over Time (MH) | M5: Regular Time (MH) | N5: Ramdan Hours | O5: Over Time (MH) | P5: Regular Time (MH) | Q5: Ramdan Hours | R5: Over Time (MH) | S5: Regular Time (MH) | T5: Ramdan Hours | U5: Over Time (MH) | V5: Regular Time (MH) | W5: Ramdan Hours | X5: Over Time (MH) | Y5: Regular Time (MH) | Z5: Ramdan Hours | AA5: Over Time (MH) | AB5: Regular Time (MH) | AC5: Ramdan Hours | AD5: Over Time (MH) | AE5: Regular Time (MH) | AF5: Ramdan Hours | AG5: Over Time (MH) | AH5: Regular Time (MH) | AI5: Ramdan Hours | AJ5: Over Time (MH) | AK5: Regular Time (MH) | AL5: Ramdan Hours | AM5: Over Time (MH) | AN5: Total Cost | AO5: Current MDs done
A6: 1 | B6: Abdelrhman Doghish | D6: KSA - Project Manager | E6: =VLOOKUP(D:D,Positions2024!A:B,2,0) | F6: ='Current Effort - Development'!$E6*1.5 | G6: 8 | J6: 88 | AN6: =SUM(G6:H6,J6:K6,M6:N6,P6:Q6,S6:T6,V6:W6,Y6:Z6,AB6:AC6,AE6:AF6,AE6:AF6,AH6:AI6,AK6:AL6)*E6+SUM(I6,L6,O6,R6,U6,X6,AA6,AD6,AG6,AJ6,AM6)*F6 | AO6: =((G6+I6+J6+L6+M6+O6+P6+R6+S6+U6+V6+X6+Y6+AA6+AB6+AD6+AE6+AG6+AH6+AJ6+AK6+AM6)/8)+((H6+K6+N6+Q6+T6+W6+Z6+AC6+AF6+AI6+AL6)/6)
A7: 2 | B7: Ahmed Araby | D7: EGY - Sr UX Designer | E7: =VLOOKUP(D:D,Positions2024!A:B,2,0) | F7: ='Current Effort - Development'!$E7*1.5 | J7: 56 | AN7: =SUM(G7:H7,J7:K7,M7:N7,P7:Q7,S7:T7,V7:W7,Y7:Z7,AB7:AC7,AE7:AF7,AE7:AF7,AH7:AI7,AK7:AL7)*E7+SUM(I7,L7,O7,R7,U7,X7,AA7,AD7,AG7,AJ7,AM7)*F7 | AO7: =((G7+I7+J7+L7+M7+O7+P7+R7+S7+U7+V7+X7+Y7+AA7+AB7+AD7+AE7+AG7+AH7+AJ7+AK7+AM7)/8)+((H7+K7+N7+Q7+T7+W7+Z7+AC7+AF7+AI7+AL7)/6)
A8: 3 | B8: Ahmed Mortdi | D8: EGY - Software Engineer | E8: =VLOOKUP(D:D,Positions2024!A:B,2,0) | F8: ='Current Effort - Development'!$E8*1.5 | J8: 44 | AN8: =SUM(G8:H8,J8:K8,M8:N8,P8:Q8,S8:T8,V8:W8,Y8:Z8,AB8:AC8,AE8:AF8,AE8:AF8,AH8:AI8,AK8:AL8)*E8+SUM(I8,L8,O8,R8,U8,X8,AA8,AD8,AG8,AJ8,AM8)*F8 | AO8: =((G8+I8+J8+L8+M8+O8+P8+R8+S8+U8+V8+X8+Y8+AA8+AB8+AD8+AE8+AG8+AH8+AJ8+AK8+AM8)/8)+((H8+K8+N8+Q8+T8+W8+Z8+AC8+AF8+AI8+AL8)/6)
A9: 4 | B9: Basem Mohamed | D9: EGY - Project Manager | E9: =VLOOKUP(D:D,Positions2024!A:B,2,0) | F9: ='Current Effort - Development'!$E9*1.5 | G9: 19 | H9: 16 | J9: 39 | AN9: =SUM(G9:H9,J9:K9,M9:N9,P9:Q9,S9:T9,V9:W9,Y9:Z9,AB9:AC9,AE9:AF9,AE9:AF9,AH9:AI9,AK9:AL9)*E9+SUM(I9,L9,O9,R9,U9,X9,AA9,AD9,AG9,AJ9,AM9)*F9 | AO9: =((G9+I9+J9+L9+M9+O9+P9+R9+S9+U9+V9+X9+Y9+AA9+AB9+AD9+AE9+AG9+AH9+AJ9+AK9+AM9)/8)+((H9+K9+N9+Q9+T9+W9+Z9+AC9+AF9+AI9+AL9)/6)
A10: 5 | B10: David Magdy | D10: EGY - Lead Software Engineer | E10: =VLOOKUP(D:D,Positions2024!A:B,2,0) | F10: ='Current Effort - Development'!$E10*1.5 | G10: 30 | J10: 32 | AN10: =SUM(G10:H10,J10:K10,M10:N10,P10:Q10,S10:T10,V10:W10,Y10:Z10,AB10:AC10,AE10:AF10,AE10:AF10,AH10:AI10,AK10:AL10)*E10+SUM(I10,L10,O10,R10,U10,X10,AA10,AD10,AG10,AJ10,AM10)*F10 | AO10: =((G10+I10+J10+L10+M10+O10+P10+R10+S10+U10+V10+X10+Y10+AA10+AB10+AD10+AE10+AG10+AH10+AJ10+AK10+AM10)/8)+((H10+K10+N10+Q10+T10+W10+Z10+AC10+AF10+AI10+AL10)/6)
A11: 6 | B11: Haitham Nabil | D11: EGY - Sr Business Analyst | E11: =VLOOKUP(D:D,Positions2024!A:B,2,0) | F11: ='Current Effort - Development'!$E11*1.5 | J11: 64 | AN11: =SUM(G11:H11,J11:K11,M11:N11,P11:Q11,S11:T11,V11:W11,Y11:Z11,AB11:AC11,AE11:AF11,AE11:AF11,AH11:AI11,AK11:AL11)*E11+SUM(I11,L11,O11,R11,U11,X11,AA11,AD11,AG11,AJ11,AM11)*F11 | AO11: =((G11+I11+J11+L11+M11+O11+P11+R11+S11+U11+V11+X11+Y11+AA11+AB11+AD11+AE11+AG11+AH11+AJ11+AK11+AM11)/8)+((H11+K11+N11+Q11+T11+W11+Z11+AC11+AF11+AI11+AL11)/6)
A12: 7 | B12: Mahmoud Spahi | D12: KSA - Solution Architect / Manager | E12: =VLOOKUP(D:D,Positions2024!A:B,2,0) | F12: ='Current Effort - Development'!$E12*1.5 | J12: 46 | AN12: =SUM(G12:H12,J12:K12,M12:N12,P12:Q12,S12:T12,V12:W12,Y12:Z12,AB12:AC12,AE12:AF12,AE12:AF12,AH12:AI12,AK12:AL12)*E12+SUM(I12,L12,O12,R12,U12,X12,AA12,AD12,AG12,AJ12,AM12)*F12 | AO12: =((G12+I12+J12+L12+M12+O12+P12+R12+S12+U12+V12+X12+Y12+AA12+AB12+AD12+AE12+AG12+AH12+AJ12+AK12+AM12)/8)+((H12+K12+N12+Q12+T12+W12+Z12+AC12+AF12+AI12+AL12)/6)
A13: 8 | B13: Menna Adel | D13: EGY - Sr UX Designer | E13: =VLOOKUP(D:D,Positions2024!A:B,2,0) | F13: ='Current Effort - Development'!$E13*1.5 | J13: 25 | AN13: =SUM(G13:H13,J13:K13,M13:N13,P13:Q13,S13:T13,V13:W13,Y13:Z13,AB13:AC13,AE13:AF13,AE13:AF13,AH13:AI13,AK13:AL13)*E13+SUM(I13,L13,O13,R13,U13,X13,AA13,AD13,AG13,AJ13,AM13)*F13 | AO13: =((G13+I13+J13+L13+M13+O13+P13+R13+S13+U13+V13+X13+Y13+AA13+AB13+AD13+AE13+AG13+AH13+AJ13+AK13+AM13)/8)+((H13+K13+N13+Q13+T13+W13+Z13+AC13+AF13+AI13+AL13)/6)
A14: 9 | B14: Moatasem Hatem | D14: EGY - Lead Business Analyst | E14: =VLOOKUP(D:D,Positions2024!A:B,2,0) | F14: ='Current Effort - Development'!$E14*1.5 | G14: 45 | H14: 73 | J14: 127.5 | AN14: =SUM(G14:H14,J14:K14,M14:N14,P14:Q14,S14:T14,V14:W14,Y14:Z14,AB14:AC14,AE14:AF14,AE14:AF14,AH14:AI14,AK14:AL14)*E14+SUM(I14,L14,O14,R14,U14,X14,AA14,AD14,AG14,AJ14,AM14)*F14 | AO14: =((G14+I14+J14+L14+M14+O14+P14+R14+S14+U14+V14+X14+Y14+AA14+AB14+AD14+AE14+AG14+AH14+AJ14+AK14+AM14)/8)+((H14+K14+N14+Q14+T14+W14+Z14+AC14+AF14+AI14+AL14)/6)
A15: 10 | B15: Moatasem Hatem | D15: EGY - Lead Business Analyst - onsite | E15: =VLOOKUP(D:D,Positions2024!A:B,2,0) | F15: ='Current Effort - Development'!$E15*1.5 | AN15: =SUM(G15:H15,J15:K15,M15:N15,P15:Q15,S15:T15,V15:W15,Y15:Z15,AB15:AC15,AE15:AF15,AE15:AF15,AH15:AI15,AK15:AL15)*E15+SUM(I15,L15,O15,R15,U15,X15,AA15,AD15,AG15,AJ15,AM15)*F15 | AO15: =((G15+I15+J15+L15+M15+O15+P15+R15+S15+U15+V15+X15+Y15+AA15+AB15+AD15+AE15+AG15+AH15+AJ15+AK15+AM15)/8)+((H15+K15+N15+Q15+T15+W15+Z15+AC15+AF15+AI15+AL15)/6)
A16: 11 | B16: Mostafa Bekhet | D16: EGY - Lead Software Engineer - onsite | E16: =VLOOKUP(D:D,Positions2024!A:B,2,0) | F16: ='Current Effort - Development'!$E16*1.5 | G16: 10 | J16: 32 | AN16: =SUM(G16:H16,J16:K16,M16:N16,P16:Q16,S16:T16,V16:W16,Y16:Z16,AB16:AC16,AE16:AF16,AE16:AF16,AH16:AI16,AK16:AL16)*E16+SUM(I16,L16,O16,R16,U16,X16,AA16,AD16,AG16,AJ16,AM16)*F16 | AO16: =((G16+I16+J16+L16+M16+O16+P16+R16+S16+U16+V16+X16+Y16+AA16+AB16+AD16+AE16+AG16+AH16+AJ16+AK16+AM16)/8)+((H16+K16+N16+Q16+T16+W16+Z16+AC16+AF16+AI16+AL16)/6)
A17: 12 | B17: Mustafa Mokhtar | D17: EGY - Sr Business Analyst - onsite | E17: =VLOOKUP(D:D,Positions2024!A:B,2,0) | F17: ='Current Effort - Development'!$E17*1.5 | H17: 12 | AN17: =SUM(G17:H17,J17:K17,M17:N17,P17:Q17,S17:T17,V17:W17,Y17:Z17,AB17:AC17,AE17:AF17,AE17:AF17,AH17:AI17,AK17:AL17)*E17+SUM(I17,L17,O17,R17,U17,X17,AA17,AD17,AG17,AJ17,AM17)*F17 | AO17: =((G17+I17+J17+L17+M17+O17+P17+R17+S17+U17+V17+X17+Y17+AA17+AB17+AD17+AE17+AG17+AH17+AJ17+AK17+AM17)/8)+((H17+K17+N17+Q17+T17+W17+Z17+AC17+AF17+AI17+AL17)/6)
A18: 13 | B18: Sandra Lateef Nashed Awad | D18: EGY - Sr Business Analyst | E18: =VLOOKUP(D:D,Positions2024!A:B,2,0) | F18: ='Current Effort - Development'!$E18*1.5 | J18: 67 | AN18: =SUM(G18:H18,J18:K18,M18:N18,P18:Q18,S18:T18,V18:W18,Y18:Z18,AB18:AC18,AE18:AF18,AE18:AF18,AH18:AI18,AK18:AL18)*E18+SUM(I18,L18,O18,R18,U18,X18,AA18,AD18,AG18,AJ18,AM18)*F18 | AO18: =((G18+I18+J18+L18+M18+O18+P18+R18+S18+U18+V18+X18+Y18+AA18+AB18+AD18+AE18+AG18+AH18+AJ18+AK18+AM18)/8)+((H18+K18+N18+Q18+T18+W18+Z18+AC18+AF18+AI18+AL18)/6)
I19: =(SUM(G6:G18)+SUM(I6:I18))/8+SUM(H6:H18)/6 | L19: =(SUM(J6:J18)+SUM(L6:L18))/8+SUM(K6:K18)/6 | AN19: =SUM(AN6:AN18) | AO19: =SUM(AO6:AO18)
D20: =214+620
F22: Total Cost in SAR | N22: =AN19*3.75
F23: Average Cost per MD | N23: =N22/AO19

Sheet Current Effort - Consultation
B1: Fill in Yellow Cells with current Team Effort
G4: May | J4: June | M4: July | P4: Augast | T4: September | W4: October | Z4: November | AC4: December | AF4: January | AI4: February | AL4: March | AO4: April
A5: # | B5: Name | D5: Position | E5: Hour Rate ($) | F5: Overtime Rate | G5: Regular Time (MH) | H5: Ramdan Hours | I5: Over Time (MH) | J5: Regular Time (MH) | K5: Ramdan Hours | L5: Over Time (MH) | M5: Regular Time (MH) | N5: Ramdan Hours | O5: Over Time (MH) | P5: Regular Time (MH) | Q5: Ramdan Hours | R5: Over Time (MH) | S5: Regular Time (MH) | T5: Ramdan Hours | U5: Over Time (MH) | V5: Regular Time (MH) | W5: Ramdan Hours | X5: Over Time (MH) | Y5: Regular Time (MH) | Z5: Ramdan Hours | AA5: Over Time (MH) | AB5: Regular Time (MH) | AC5: Ramdan Hours | AD5: Over Time (MH) | AE5: Regular Time (MH) | AF5: Ramdan Hours | AG5: Over Time (MH) | AH5: Regular Time (MH) | AI5: Ramdan Hours | AJ5: Over Time (MH) | AK5: Regular Time (MH) | AL5: Ramdan Hours | AM5: Over Time (MH) | AN5: Regular Time (MH) | AO5: Ramdan Hours | AP5: Over Time (MH) | AQ5: Total Cost | AR5: Current MDs done
A6: 1 | B6: Abdelrhman Doghish | D6: KSA - Project Manager | E6: =VLOOKUP(D:D,Positions2024!A:B,2,0) | F6: ='Current Effort - Consultation'!$E6*1.5 | J6: 56 | M6: 96 | P6: 128 | S6: 168 | V6: 168 | Y6: =160+8 | AB6: 136 | AE6: 128 | AH6: 104 | AI6: 36 | AK6: =8*4 | AL6: 84 | AN6: 80 | AQ6: =SUM(G6:H6,J6:K6,M6:N6,P6:Q6,S6:T6,V6:W6,Y6:Z6,AB6:AC6,AE6:AF6,AE6:AF6,AH6:AI6,AK6:AL6,AN6:AO6)*E6+SUM(I6,L6,O6,R6,U6,X6,AA6,AD6,AG6,AJ6,AM6,AP6)*F6 | AR6: =((G6+I6+J6+L6+M6+O6+P6+R6+S6+U6+V6+X6+Y6+AA6+AB6+AD6+AE6+AG6+AH6+AJ6+AK6+AM6+AN6+AP6)/8)+((H6+K6+N6+Q6+T6+W6+Z6+AC6+AF6+AI6+AL6+AO6)/6)
A7: 2 | B7: Talal Abdulwahed | D7: KSA - Solution Architect / Manager | E7: =VLOOKUP(D:D,Positions2024!A:B,2,0) | F7: ='Current Effort - Consultation'!$E7*1.5 | J7: 56 | M7: 152 | P7: 160 | S7: 160 | V7: 160 | Y7: =160+8 | AB7: 136 | AE7: 168 | AH7: 104 | AI7: 36 | AK7: 40 | AL7: 94.5 | AN7: 149 | AQ7: =SUM(G7:H7,J7:K7,M7:N7,P7:Q7,S7:T7,V7:W7,Y7:Z7,AB7:AC7,AE7:AF7,AE7:AF7,AH7:AI7,AK7:AL7,AN7:AO7)*E7+SUM(I7,L7,O7,R7,U7,X7,AA7,AD7,AG7,AJ7,AM7,AP7)*F7 | AR7: =((G7+I7+J7+L7+M7+O7+P7+R7+S7+U7+V7+X7+Y7+AA7+AB7+AD7+AE7+AG7+AH7+AJ7+AK7+AM7+AN7+AP7)/8)+((H7+K7+N7+Q7+T7+W7+Z7+AC7+AF7+AI7+AL7+AO7)/6)
A8: 3 | B8: Abeer AbdelHameed | D8: EGY - Business Analyst - onsite | E8: =VLOOKUP(D:D,Positions2024!A:B,2,0) | F8: ='Current Effort - Consultation'!$E8*1.5 | J8: 52 | L8: 8 | M8: 168 | O8: 16 | P8: 167 | S8: 144 | V8: =159-X8 | X8: 8 | Y8: =152+16 | AB8: =167+16 | AQ8: =SUM(G8:H8,J8:K8,M8:N8,P8:Q8,S8:T8,V8:W8,Y8:Z8,AB8:AC8,AE8:AF8,AE8:AF8,AH8:AI8,AK8:AL8,AN8:AO8)*E8+SUM(I8,L8,O8,R8,U8,X8,AA8,AD8,AG8,AJ8,AM8,AP8)*F8 | AR8: =((G8+I8+J8+L8+M8+O8+P8+R8+S8+U8+V8+X8+Y8+AA8+AB8+AD8+AE8+AG8+AH8+AJ8+AK8+AM8+AN8+AP8)/8)+((H8+K8+N8+Q8+T8+W8+Z8+AC8+AF8+AI8+AL8+AO8)/6)
A9: 4 | B9: Abeer AbdelHameed | D9: EGY - Sr Business Analyst - onsite | E9: =VLOOKUP(D:D,Positions2024!A:B,2,0) | F9: ='Current Effort - Consultation'!$E9*1.5 | AE9: =129-AG9 | AG9: 4 | AH9: 104 | AI9: 36 | AK9: 48 | AL9: =92-AM9 | AM9: 16.5 | AN9: =138.5-AN10 | AQ9: =SUM(G9:H9,J9:K9,M9:N9,P9:Q9,S9:T9,V9:W9,Y9:Z9,AB9:AC9,AE9:AF9,AE9:AF9,AH9:AI9,AK9:AL9,AN9:AO9)*E9+SUM(I9,L9,O9,R9,U9,X9,AA9,AD9,AG9,AJ9,AM9,AP9)*F9 | AR9: =((G9+I9+J9+L9+M9+O9+P9+R9+S9+U9+V9+X9+Y9+AA9+AB9+AD9+AE9+AG9+AH9+AJ9+AK9+AM9+AN9+AP9)/8)+((H9+K9+N9+Q9+T9+W9+Z9+AC9+AF9+AI9+AL9+AO9)/6)
B10: Abeer AbdelHameed | D10: EGY - Sr Business Analyst | E10: =VLOOKUP(D:D,Positions2024!A:B,2,0) | F10: ='Current Effort - Consultation'!$E10*1.5 | AN10: =138.5-114 | AQ10: =SUM(G10:H10,J10:K10,M10:N10,P10:Q10,S10:T10,V10:W10,Y10:Z10,AB10:AC10,AE10:AF10,AE10:AF10,AH10:AI10,AK10:AL10,AN10:AO10)*E10+SUM(I10,L10,O10,R10,U10,X10,AA10,AD10,AG10,AJ10,AM10,AP10)*F10 | AR10: =((G10+I10+J10+L10+M10+O10+P10+R10+S10+U10+V10+X10+Y10+AA10+AB10+AD10+AE10+AG10+AH10+AJ10+AK10+AM10+AN10+AP10)/8)+((H10+K10+N10+Q10+T10+W10+Z10+AC10+AF10+AI10+AL10+AO10)/6)
A11: 5 | B11: Ahmed Araby | D11: EGY - Sr UX Designer | E11: =VLOOKUP(D:D,Positions2024!A:B,2,0) | F11: ='Current Effort - Consultation'!$E11*1.5 | Y11: =112+24 | AQ11: =SUM(G11:H11,J11:K11,M11:N11,P11:Q11,S11:T11,V11:W11,Y11:Z11,AB11:AC11,AE11:AF11,AE11:AF11,AH11:AI11,AK11:AL11,AN11:AO11)*E11+SUM(I11,L11,O11,R11,U11,X11,AA11,AD11,AG11,AJ11,AM11,AP11)*F11 | AR11: =((G11+I11+J11+L11+M11+O11+P11+R11+S11+U11+V11+X11+Y11+AA11+AB11+AD11+AE11+AG11+AH11+AJ11+AK11+AM11+AN11+AP11)/8)+((H11+K11+N11+Q11+T11+W11+Z11+AC11+AF11+AI11+AL11+AO11)/6)
A12: 6 | B12: Amr Ahmed | D12: EGY - Sr UX Designer | E12: =VLOOKUP(D:D,Positions2024!A:B,2,0) | F12: ='Current Effort - Consultation'!$E12*1.5 | V12: 16 | Y12: 13 | AQ12: =SUM(G12:H12,J12:K12,M12:N12,P12:Q12,S12:T12,V12:W12,Y12:Z12,AB12:AC12,AE12:AF12,AE12:AF12,AH12:AI12,AK12:AL12,AN12:AO12)*E12+SUM(I12,L12,O12,R12,U12,X12,AA12,AD12,AG12,AJ12,AM12,AP12)*F12 | AR12: =((G12+I12+J12+L12+M12+O12+P12+R12+S12+U12+V12+X12+Y12+AA12+AB12+AD12+AE12+AG12+AH12+AJ12+AK12+AM12+AN12+AP12)/8)+((H12+K12+N12+Q12+T12+W12+Z12+AC12+AF12+AI12+AL12+AO12)/6)
A13: 7 | B13: Bushra ElGhamdi | D13: KSA - Business Analyst | E13: =VLOOKUP(D:D,Positions2024!A:B,2,0) | F13: ='Current Effort - Consultation'!$E13*1.5 | J13: 80.5 | M13: 174 | P13: 160 | S13: =138+24 | V13: 152 | Y13: =136+24 | AB13: =156+16 | AQ13: =SUM(G13:H13,J13:K13,M13:N13,P13:Q13,S13:T13,V13:W13,Y13:Z13,AB13:AC13,AE13:AF13,AE13:AF13,AH13:AI13,AK13:AL13,AN13:AO13)*E13+SUM(I13,L13,O13,R13,U13,X13,AA13,AD13,AG13,AJ13,AM13,AP13)*F13 | AR13: =((G13+I13+J13+L13+M13+O13+P13+R13+S13+U13+V13+X13+Y13+AA13+AB13+AD13+AE13+AG13+AH13+AJ13+AK13+AM13+AN13+AP13)/8)+((H13+K13+N13+Q13+T13+W13+Z13+AC13+AF13+AI13+AL13+AO13)/6)
A14: 8 | B14: Bushra ElGhamdi | D14: KSA- Sr Business Analyst | E14: =VLOOKUP(D:D,Positions2024!A:B,2,0) | F14: ='Current Effort - Consultation'!$E14*1.5 | AE14: 152 | AH14: 96 | AI14: 24 | AK14: 7 | AL14: =96.5-AM14 | AM14: 18.5 | AN14: 80 | AQ14: =SUM(G14:H14,J14:K14,M14:N14,P14:Q14,S14:T14,V14:W14,Y14:Z14,AB14:AC14,AE14:AF14,AE14:AF14,AH14:AI14,AK14:AL14,AN14:AO14)*E14+SUM(I14,L14,O14,R14,U14,X14,AA14,AD14,AG14,AJ14,AM14,AP14)*F14 | AR14: =((G14+I14+J14+L14+M14+O14+P14+R14+S14+U14+V14+X14+Y14+AA14+AB14+AD14+AE14+AG14+AH14+AJ14+AK14+AM14+AN14+AP14)/8)+((H14+K14+N14+Q14+T14+W14+Z14+AC14+AF14+AI14+AL14+AO14)/6)
A15: 9 | B15: Dina Said | D15: EGY - Lead Business Analyst | E15: =VLOOKUP(D:D,Positions2024!A:B,2,0) | F15: ='Current Effort - Consultation'!$E15*1.5 | J15: 3 | M15: 122 | P15: 5 | AQ15: =SUM(G15:H15,J15:K15,M15:N15,P15:Q15,S15:T15,V15:W15,Y15:Z15,AB15:AC15,AE15:AF15,AE15:AF15,AH15:AI15,AK15:AL15,AN15:AO15)*E15+SUM(I15,L15,O15,R15,U15,X15,AA15,AD15,AG15,AJ15,AM15,AP15)*F15 | AR15: =((G15+I15+J15+L15+M15+O15+P15+R15+S15+U15+V15+X15+Y15+AA15+AB15+AD15+AE15+AG15+AH15+AJ15+AK15+AM15+AN15+AP15)/8)+((H15+K15+N15+Q15+T15+W15+Z15+AC15+AF15+AI15+AL15+AO15)/6)
A16: 10 | B16: Emad Elgabri | D16: KSA - Solution Architect / Manager | E16: =VLOOKUP(D:D,Positions2024!A:B,2,0) | F16: ='Current Effort - Consultation'!$E16*1.5 | M16: 72 | P16: 168 | S16: 170 | V16: 168 | Y16: =144+16 | AB16: =168+16 | AE16: 152 | AH16: 88 | AI16: 36 | AK16: 40 | AL16: 84 | AN16: 152 | AQ16: =SUM(G16:H16,J16:K16,M16:N16,P16:Q16,S16:T16,V16:W16,Y16:Z16,AB16:AC16,AE16:AF16,AE16:AF16,AH16:AI16,AK16:AL16,AN16:AO16)*E16+SUM(I16,L16,O16,R16,U16,X16,AA16,AD16,AG16,AJ16,AM16,AP16)*F16 | AR16: =((G16+I16+J16+L16+M16+O16+P16+R16+S16+U16+V16+X16+Y16+AA16+AB16+AD16+AE16+AG16+AH16+AJ16+AK16+AM16+AN16+AP16)/8)+((H16+K16+N16+Q16+T16+W16+Z16+AC16+AF16+AI16+AL16+AO16)/6)
A17: 11 | B17: Kareem Waleed | D17: EGY - Lead Business Analyst - onsite | E17: =VLOOKUP(D:D,Positions2024!A:B,2,0) | F17: ='Current Effort - Consultation'!$E17*1.5 | Y17: =188+16 | AB17: 197 | AE17: =146-AG17 | AG17: 8 | AH17: 97.5 | AI17: 24 | AK17: 16 | AL17: 77 | AN17: 91 | AQ17: =SUM(G17:H17,J17:K17,M17:N17,P17:Q17,S17:T17,V17:W17,Y17:Z17,AB17:AC17,AE17:AF17,AE17:AF17,AH17:AI17,AK17:AL17,AN17:AO17)*E17+SUM(I17,L17,O17,R17,U17,X17,AA17,AD17,AG17,AJ17,AM17,AP17)*F17 | AR17: =((G17+I17+J17+L17+M17+O17+P17+R17+S17+U17+V17+X17+Y17+AA17+AB17+AD17+AE17+AG17+AH17+AJ17+AK17+AM17+AN17+AP17)/8)+((H17+K17+N17+Q17+T17+W17+Z17+AC17+AF17+AI17+AL17+AO17)/6)
B18: Kareem Waleed | D18: EGY - Lead Business Analyst | E18: =VLOOKUP(D:D,Positions2024!A:B,2,0) | F18: ='Current Effort - Consultation'!$E18*1.5 | AN18: =171.5-91 | AQ18: =SUM(G18:H18,J18:K18,M18:N18,P18:Q18,S18:T18,V18:W18,Y18:Z18,AB18:AC18,AE18:AF18,AE18:AF18,AH18:AI18,AK18:AL18,AN18:AO18)*E18+SUM(I18,L18,O18,R18,U18,X18,AA18,AD18,AG18,AJ18,AM18,AP18)*F18 | AR18: =((G18+I18+J18+L18+M18+O18+P18+R18+S18+U18+V18+X18+Y18+AA18+AB18+AD18+AE18+AG18+AH18+AJ18+AK18+AM18+AN18+AP18)/8)+((H18+K18+N18+Q18+T18+W18+Z18+AC18+AF18+AI18+AL18+AO18)/6)
A19: 12 | B19: Menna Adel | D19: EGY - Sr UX Designer | E19: =VLOOKUP(D:D,Positions2024!A:B,2,0) | F19: ='Current Effort - Consultation'!$E19*1.5 | S19: 40 | V19: 18 | Y19: 75 | AB19: 176 | AE19: 48 | AH19: 30 | AL19: 30 | AQ19: =SUM(G19:H19,J19:K19,M19:N19,P19:Q19,S19:T19,V19:W19,Y19:Z19,AB19:AC19,AE19:AF19,AE19:AF19,AH19:AI19,AK19:AL19,AN19:AO19)*E19+SUM(I19,L19,O19,R19,U19,X19,AA19,AD19,AG19,AJ19,AM19,AP19)*F19 | AR19: =((G19+I19+J19+L19+M19+O19+P19+R19+S19+U19+V19+X19+Y19+AA19+AB19+AD19+AE19+AG19+AH19+AJ19+AK19+AM19+AN19+AP19)/8)+((H19+K19+N19+Q19+T19+W19+Z19+AC19+AF19+AI19+AL19+AO19)/6)
A20: 13 | B20: Mohammad Nabil | D20: EGY - Project Manager | E20: =VLOOKUP(D:D,Positions2024!A:B,2,0) | F20: ='Current Effort - Consultation'!$E20*1.5 | AL20: 6 | AN20: 4 | AQ20: =SUM(G20:H20,J20:K20,M20:N20,P20:Q20,S20:T20,V20:W20,Y20:Z20,AB20:AC20,AE20:AF20,AE20:AF20,AH20:AI20,AK20:AL20,AN20:AO20)*E20+SUM(I20,L20,O20,R20,U20,X20,AA20,AD20,AG20,AJ20,AM20,AP20)*F20 | AR20: =((G20+I20+J20+L20+M20+O20+P20+R20+S20+U20+V20+X20+Y20+AA20+AB20+AD20+AE20+AG20+AH20+AJ20+AK20+AM20+AN20+AP20)/8)+((H20+K20+N20+Q20+T20+W20+Z20+AC20+AF20+AI20+AL20+AO20)/6)
A21: 14 | B21: Mohamed Abdallah | D21: KSA - Project Manager | E21: =VLOOKUP(D:D,Positions2024!A:B,2,0) | F21: ='Current Effort - Consultation'!$E21*1.5 | M21: 110 | P21: 44 | AQ21: =SUM(G21:H21,J21:K21,M21:N21,P21:Q21,S21:T21,V21:W21,Y21:Z21,AB21:AC21,AE21:AF21,AE21:AF21,AH21:AI21,AK21:AL21,AN21:AO21)*E21+SUM(I21,L21,O21,R21,U21,X21,AA21,AD21,AG21,AJ21,AM21,AP21)*F21 | AR21: =((G21+I21+J21+L21+M21+O21+P21+R21+S21+U21+V21+X21+Y21+AA21+AB21+AD21+AE21+AG21+AH21+AJ21+AK21+AM21+AN21+AP21)/8)+((H21+K21+N21+Q21+T21+W21+Z21+AC21+AF21+AI21+AL21+AO21)/6)
A22: 15 | B22: Mohamed Eldegwy | D22: EGY - Lead UX Designer | E22: =VLOOKUP(D:D,Positions2024!A:B,2,0) | F22: ='Current Effort - Consultation'!$E22*1.5 | S22: 24 | V22: 32 | Y22: 18 | AQ22: =SUM(G22:H22,J22:K22,M22:N22,P22:Q22,S22:T22,V22:W22,Y22:Z22,AB22:AC22,AE22:AF22,AE22:AF22,AH22:AI22,AK22:AL22,AN22:AO22)*E22+SUM(I22,L22,O22,R22,U22,X22,AA22,AD22,AG22,AJ22,AM22,AP22)*F22 | AR22: =((G22+I22+J22+L22+M22+O22+P22+R22+S22+U22+V22+X22+Y22+AA22+AB22+AD22+AE22+AG22+AH22+AJ22+AK22+AM22+AN22+AP22)/8)+((H22+K22+N22+Q22+T22+W22+Z22+AC22+AF22+AI22+AL22+AO22)/6)
A23: 16 | B23: Mohamed Foad | D23: KSA - Solution Architect / Manager | E23: =VLOOKUP(D:D,Positions2024!A:B,2,0) | F23: ='Current Effort - Consultation'!$E23*1.5 | I23: 31 | L23: 13 | O23: 8.5 | R23: 21.5 | AA23: 24 | AQ23: =SUM(G23:H23,J23:K23,M23:N23,P23:Q23,S23:T23,V23:W23,Y23:Z23,AB23:AC23,AE23:AF23,AE23:AF23,AH23:AI23,AK23:AL23,AN23:AO23)*E23+SUM(I23,L23,O23,R23,U23,X23,AA23,AD23,AG23,AJ23,AM23,AP23)*F23 | AR23: =((G23+I23+J23+L23+M23+O23+P23+R23+S23+U23+V23+X23+Y23+AA23+AB23+AD23+AE23+AG23+AH23+AJ23+AK23+AM23+AN23+AP23)/8)+((H23+K23+N23+Q23+T23+W23+Z23+AC23+AF23+AI23+AL23+AO23)/6)
A24: 17 | B24: Khaled Elbialy | D24: EGY - Sr Business Analyst - onsite | E24: =VLOOKUP(D:D,Positions2024!A:B,2,0) | F24: ='Current Effort - Consultation'!$E24*1.5 | S24: 138 | V24: =176-X24 | X24: 8 | Y24: =152+8 | AB24: 96 | AE24: =160-AG24 | AG24: 8 | AH24: 95 | AI24: 36 | AK24: 36 | AL24: 84 | AN24: 56 | AQ24: =SUM(G24:H24,J24:K24,M24:N24,P24:Q24,S24:T24,V24:W24,Y24:Z24,AB24:AC24,AE24:AF24,AE24:AF24,AH24:AI24,AK24:AL24,AN24:AO24)*E24+SUM(I24,L24,O24,R24,U24,X24,AA24,AD24,AG24,AJ24,AM24,AP24)*F24 | AR24: =((G24+I24+J24+L24+M24+O24+P24+R24+S24+U24+V24+X24+Y24+AA24+AB24+AD24+AE24+AG24+AH24+AJ24+AK24+AM24+AN24+AP24)/8)+((H24+K24+N24+Q24+T24+W24+Z24+AC24+AF24+AI24+AL24+AO24)/6)
B25: Khaled Elbialy | D25: EGY - Sr Business Analyst | E25: =VLOOKUP(D:D,Positions2024!A:B,2,0) | F25: ='Current Effort - Consultation'!$E25*1.5 | AN25: =161-AN24 | AQ25: =SUM(G25:H25,J25:K25,M25:N25,P25:Q25,S25:T25,V25:W25,Y25:Z25,AB25:AC25,AE25:AF25,AE25:AF25,AH25:AI25,AK25:AL25,AN25:AO25)*E25+SUM(I25,L25,O25,R25,U25,X25,AA25,AD25,AG25,AJ25,AM25,AP25)*F25 | AR25: =((G25+I25+J25+L25+M25+O25+P25+R25+S25+U25+V25+X25+Y25+AA25+AB25+AD25+AE25+AG25+AH25+AJ25+AK25+AM25+AN25+AP25)/8)+((H25+K25+N25+Q25+T25+W25+Z25+AC25+AF25+AI25+AL25+AO25)/6)
A26: 18 | B26: Moahmed Ismail | D26: KSA - Solution Architect / Manager | E26: =VLOOKUP(D:D,Positions2024!A:B,2,0) | F26: ='Current Effort - Consultation'!$E26*1.5 | M26: 58 | P26: 149 | S26: 144 | V26: 116 | Y26: 101 | AB26: 121 | AE26: 104 | AH26: 32 | AL26: 18 | AQ26: =SUM(G26:H26,J26:K26,M26:N26,P26:Q26,S26:T26,V26:W26,Y26:Z26,AB26:AC26,AE26:AF26,AE26:AF26,AH26:AI26,AK26:AL26,AN26:AO26)*E26+SUM(I26,L26,O26,R26,U26,X26,AA26,AD26,AG26,AJ26,AM26,AP26)*F26 | AR26: =((G26+I26+J26+L26+M26+O26+P26+R26+S26+U26+V26+X26+Y26+AA26+AB26+AD26+AE26+AG26+AH26+AJ26+AK26+AM26+AN26+AP26)/8)+((H26+K26+N26+Q26+T26+W26+Z26+AC26+AF26+AI26+AL26+AO26)/6)
A27: 19 | B27: Mostafa Mokhtar | D27: EGY - Sr. Software Engineer - onsite | E27: =VLOOKUP(D:D,Positions2024!A:B,2,0) | F27: ='Current Effort - Consultation'!$E27*1.5 | AK27: 1 | AL27: 1 | AN27: 1 | AQ27: =SUM(G27:H27,J27:K27,M27:N27,P27:Q27,S27:T27,V27:W27,Y27:Z27,AB27:AC27,AE27:AF27,AE27:AF27,AH27:AI27,AK27:AL27,AN27:AO27)*E27+SUM(I27,L27,O27,R27,U27,X27,AA27,AD27,AG27,AJ27,AM27,AP27)*F27 | AR27: =((G27+I27+J27+L27+M27+O27+P27+R27+S27+U27+V27+X27+Y27+AA27+AB27+AD27+AE27+AG27+AH27+AJ27+AK27+AM27+AN27+AP27)/8)+((H27+K27+N27+Q27+T27+W27+Z27+AC27+AF27+AI27+AL27+AO27)/6)
A28: 20 | B28: Shady Mahfouz | D28: EGY - Business Analyst - onsite | E28: =VLOOKUP(D:D,Positions2024!A:B,2,0) | F28: ='Current Effort - Consultation'!$E28*1.5 | P28: 6 | S28: 180 | V28: =179-X28 | X28: 11 | Y28: =156+8 | AB28: =96+8 | AE28: =168-AG28 | AG28: 8 | AH28: 104 | AI28: 36 | AK28: 24 | AL28: 84 | AQ28: =SUM(G28:H28,J28:K28,M28:N28,P28:Q28,S28:T28,V28:W28,Y28:Z28,AB28:AC28,AE28:AF28,AE28:AF28,AH28:AI28,AK28:AL28,AN28:AO28)*E28+SUM(I28,L28,O28,R28,U28,X28,AA28,AD28,AG28,AJ28,AM28,AP28)*F28 | AR28: =((G28+I28+J28+L28+M28+O28+P28+R28+S28+U28+V28+X28+Y28+AA28+AB28+AD28+AE28+AG28+AH28+AJ28+AK28+AM28+AN28+AP28)/8)+((H28+K28+N28+Q28+T28+W28+Z28+AC28+AF28+AI28+AL28+AO28)/6)
A29: 21 | B29: Shady Mahfouz | D29: EGY - Business Analyst | E29: =VLOOKUP(D:D,Positions2024!A:B,2,0) | F29: ='Current Effort - Consultation'!$E29*1.5 | AN29: 158 | AQ29: =SUM(G29:H29,J29:K29,M29:N29,P29:Q29,S29:T29,V29:W29,Y29:Z29,AB29:AC29,AE29:AF29,AE29:AF29,AH29:AI29,AK29:AL29,AN29:AO29)*E29+SUM(I29,L29,O29,R29,U29,X29,AA29,AD29,AG29,AJ29,AM29,AP29)*F29 | AR29: =((G29+I29+J29+L29+M29+O29+P29+R29+S29+U29+V29+X29+Y29+AA29+AB29+AD29+AE29+AG29+AH29+AJ29+AK29+AM29+AN29+AP29)/8)+((H29+K29+N29+Q29+T29+W29+Z29+AC29+AF29+AI29+AL29+AO29)/6)
A30: 22 | B30: Njoud ElMubarek | D30: KSA - Business Analyst | E30: =VLOOKUP(D:D,Positions2024!A:B,2,0) | F30: ='Current Effort - Consultation'!$E30*1.5 | J30: 88 | M30: 176 | P30: 120 | AQ30: =SUM(G30:H30,J30:K30,M30:N30,P30:Q30,S30:T30,V30:W30,Y30:Z30,AB30:AC30,AE30:AF30,AE30:AF30,AH30:AI30,AK30:AL30,AN30:AO30)*E30+SUM(I30,L30,O30,R30,U30,X30,AA30,AD30,AG30,AJ30,AM30,AP30)*F30 | AR30: =((G30+I30+J30+L30+M30+O30+P30+R30+S30+U30+V30+X30+Y30+AA30+AB30+AD30+AE30+AG30+AH30+AJ30+AK30+AM30+AN30+AP30)/8)+((H30+K30+N30+Q30+T30+W30+Z30+AC30+AF30+AI30+AL30+AO30)/6)
I31: =(SUM(G6:G30)+SUM(I6:I30))/8+SUM(H6:H30)/6 | L31: =(SUM(J6:J30)+SUM(L6:L30))/8+SUM(K6:K30)/6 | O31: =(SUM(M6:M30)+SUM(O6:O30))/8+SUM(N6:N30)/6 | R31: =(SUM(P6:P30)+SUM(R6:R30))/8+SUM(Q6:Q30)/6 | U31: =(SUM(S6:S30)+SUM(U6:U30))/8+SUM(T6:T30)/6 | X31: =(SUM(V6:V30)+SUM(X6:X30))/8+SUM(W6:W30)/6 | AA31: =(SUM(Y6:Y30)+SUM(AA6:AA30))/8+SUM(Z6:Z30)/6 | AD31: =(SUM(AB6:AB30)+SUM(AD6:AD30))/8+SUM(AC6:AC30)/6 | AG31: =(SUM(AE6:AE30)+SUM(AG6:AG30))/8+SUM(AF6:AF30)/6 | AJ31: =(SUM(AH6:AH30)+SUM(AJ6:AJ30))/8+SUM(AI6:AI30)/6 | AM31: =(SUM(AK6:AK30)+SUM(AM6:AM30))/8+SUM(AL6:AL30)/6 | AP31: =(SUM(AN6:AN30)+SUM(AP6:AP30))/8+SUM(AO6:AO30)/6 | AQ31: =SUM(AQ6:AQ30) | AR31: =SUM(AR6:AR30)
F34: Total Cost in SAR | N34: =AQ31*3.75
F35: Average Cost per MD | N35: =N34/AR31
D37: 10 | E37: 11
B38: Abdelrhman Doghish | C38: 112.25 | D38: 176 | E38: 168
B39: Talal Abdulwahed | C39: 112.25 | D39: 176 | E39: 168
B40: Abeer AbdelHameed | C40: 45.215 | D40: 176 | E40: 168
B41: Bushra ElGhamdi | C41: 56.25 | D41: 176 | E41: 168
B42: Emad Elgabri | C42: 112.25 | D42: 176 | E42: 168
B43: Khaled Elbialy | C43: 51.63125 | D43: 176 | E43: 168
B44: Moahmed Ismail | C44: 112.25 | D44: 176 | E44: 168
B45: Shady Mahfouz | C45: 45.215 | D45: 176 | E45: 168
...

Sheet Profitability - Consultation
A1: Project Name | F1: PM Name
A2: Contract Start Date | F2: Contract End Date | J2: Current Scope
A3: Support Start Date | F3: Support End Date
A4: Licenses and 3rd party Revenue | F4: Licenses and 3rd party Cost
C5: Presales Budget | F5: Current Month calculations | P5: Cost Variance | T5: Profitability | W5: Profit Variance | Y5: Progress and Virtual Invoices for fixed cost
A6: Month | B6: Consumed Revenue | C6: Total Revenue (SAR) | D6: Total Estimated Cost (SAR) | E6: Estimated Effort MDs | F6: This month MDs | G6: Actual Effort to Date (MD) | H6: % Completion from plan | I6: Current Cost (SAR) | J6: Estimated Remaining (MD) | K6: EAC MDs | L6: Expected overrun (SAR) | M6: Revenue to date | N6: Estimated Cost to Complete | O6: Estimate at Completion | P6: CPI | Q6: Variance | R6: Variance (%) | T6: Profit at Completion | U6: Planned Profit | V6: Profit at Completion (%) | W6: Profitability Variance | X6: Profitability Variance (%) | Y6: Total Issued Invoices (SAR) | Z6: Progress % | AA6: Total Recognized Revenue | AB6: Production | AC6: Accumulative virtual invoice | AD6: This month Virtual Invoice | AE6: VI+Issued
I7: (7) | J7: (8) | N7: (9) | O7: (10) | Q7: (11) | R7: (12) | T7: (13) | V7: (14) | W7: (15) | X7: (16) | Y7: (17) | Z7: (18) | AA7: (19)
A8: 45798 | C8: ='Budget - Consultation'!$E$17 | D8: ='Budget - Consultation'!$E$16 | E8: ='Budget - Consultation'!$E$12 | F8: ='Current Effort - Consultation'!I31 | G8: 3.88 | H8: 0.01 | I8: 19573.59 | J8: =E8-G8 | K8: =J8+G8 | L8: =(G8/E8)/H8-100% | M8: =H8*C8 | N8: =J8*'Current Effort - Consultation'!$N$35 | O8: =N8+I8 | P8: =D8/O8 | Q8: ='Budget - Consultation'!$I$15-O8 | R8: =Q8/'Budget - Consultation'!$I$16 | T8: ='Budget - Consultation'!$I$16-O8 | U8: ='Budget - Consultation'!$E$19 | V8: =T8/'Budget - Consultation'!$I$16 | W8: =T8-'Budget - Consultation'!$I$17 | X8: =V8-'Budget - Consultation'!$I$18 | Y8: 0 | Z8: =H8 | AA8: =C8*Z8 | AB8: =AA8-AA7 | AC8: =AA8-Y8 | AD8: =AC8-AC7 | AE8: =AC8+Y8
A9: 45829 | C9: ='Budget - Consultation'!$E$17 | D9: ='Budget - Consultation'!$E$16 | E9: ='Budget - Consultation'!$E$12 | F9: ='Current Effort - Consultation'!L31 | G9: =F9+G8 | H9: 0.02 | I9: 121184.57 | J9: =E9-G9 | K9: =J9+G9 | L9: =(G9/E9)/H9-100% | M9: =H9*C9 | N9: =J9*'Current Effort - Consultation'!$N$35 | O9: =N9+I9 | P9: =D9/O9 | Q9: ='Budget - Consultation'!$I$15-O9 | R9: =Q9/'Budget - Consultation'!$I$16 | T9: ='Budget - Consultation'!$I$16-O9 | U9: ='Budget - Consultation'!$E$19 | V9: =T9/'Budget - Consultation'!$I$16 | W9: =T9-'Budget - Consultation'!$I$17 | X9: =V9-'Budget - Consultation'!$I$18 | Y9: 0 | Z9: =H9 | AA9: =C9*H9 | AB9: =AA9-AA8 | AC9: =AA9-Y9 | AD9: =AC9-AC8 | AE9: =AC9+Y9
A10: 45859 | C10: ='Budget - Consultation'!$E$17 | D10: ='Budget - Consultation'!$E$16 | E10: ='Budget - Consultation'!$E$12 | F10: ='Current Effort - Consultation'!O31 | G10: =F10+G9 | H10: 0.08 | I10: 454192.88 | J10: =E10-G10 | K10: =J10+G10 | L10: =(G10/E10)/H10-100% | M10: =H10*C10 | N10: =J10*'Current Effort - Consultation'!$N$35 | O10: =N10+I10 | P10: =D10/O10 | Q10: ='Budget - Consultation'!$I$15-O10 | R10: =Q10/'Budget - Consultation'!$I$16 | T10: ='Budget - Consultation'!$I$16-O10 | U10: ='Budget - Consultation'!$E$19 | V10: =T10/'Budget - Consultation'!$I$16 | W10: =T10-'Budget - Consultation'!$I$17 | X10: =V10-'Budget - Consultation'!$I$18 | Y10: 0 | Z10: =H10 | AA10: =C10*H10 | AB10: =AA10-AA9 | AC10: =AA10-Y10 | AD10: =AC10-AC9 | AE10: =AC10+Y10
A11: 45890 | C11: ='Budget - Consultation'!$E$17 | D11: ='Budget - Consultation'!$E$16 | E11: ='Budget - Consultation'!$E$12 | F11: ='Current Effort - Consultation'!R31 | G11: =F11+G10 | H11: 0.18 | I11: 807937.08 | J11: =E11-G11 | K11: =J11+G11 | L11: =(G11/E11)/H11-100% | M11: =H11*C11 | N11: =J11*'Current Effort - Consultation'!$N$35 | O11: =N11+I11 | P11: =D11/O11 | Q11: ='Budget - Consultation'!$I$15-O11 | R11: =Q11/'Budget - Consultation'!$I$16 | T11: ='Budget - Consultation'!$I$16-O11 | U11: ='Budget - Consultation'!$E$19 | V11: =T11/'Budget - Consultation'!$I$16 | W11: =T11-'Budget - Consultation'!$I$17 | X11: =V11-'Budget - Consultation'!$I$18 | Y11: 0 | Z11: =H11 | AA11: =C11*H11 | AB11: =AA11-AA10 | AC11: =AA11-Y11 | AD11: =AC11-AC10 | AE11: =AC11+Y11
A12: 45921 | C12: 6641250 | D12: 4811400 | E12: 1848 | F12: 166.25 | G12: =F12+G11 | H12: 0.25 | I12: 1224457.1 | J12: 1678.25 | K12: =J12+G12 | L12: =(G12/E12)/H12-100% | M12: 1660312.5 | N12: 4111431.9 | O12: 5335889 | P12: 0.90170542 | Q12: -524488.97 | R12: -0.078974435 | T12: 1305361 | U12: 0.27552795 | V12: 0.19655352 | W12: -524488.97 | X12: -0.078974435 | Y12: 0 | Z12: =I12/O12 | AA12: =C12*H12 | AB12: =AA12-AA11 | AC12: =AA12-Y12 | AD12: =AC12-AC11 | AE12: =AC12+Y12
A13: 45951 | C13: 6641250 | D13: 4811400 | E13: 1848 | F13: 168 | G13: =F13+G12 | H13: 0.35 | I13: 1616092.4 | J13: 1181 | K13: =J13+G13 | L13: =(G13/E13)/H13-100% | M13: =H13*C13 | N13: 2857995.5 | O13: 4474087.9 | P13: 1.0753924 | Q13: 337312.13 | R13: 0.050790458 | T13: 2167162.1 | U13: 0.27552795 | V13: 0.32631841 | W13: 337312.13 | X13: 0.050790458 | Y13: 0 | Z13: 0.36121159 | AA13: 2324437.5 | AB13: =AA13-AA12 | AC13: 2324437.5 | AD13: =AC13-AC12 | AE13: =AC13+Y13
A14: 45982 | C14: 6641250 | D14: 4811400 | E14: 1848 | F14: 214.875 | G14: =F14+G13 | H14: 0.48 | I14: 2067058.9 | J14: 955 | K14: =J14+G14 | L14: =(G14/E14)/H14-100% | M14: =H14*C14 | N14: 2236398.8 | O14: 4303457.7 | P14: 1.1180312 | Q14: 507942.29 | R14: 0.076482935 | T14: 2337792.3 | U14: 0.27552795 | V14: 0.35201089 | W14: 507942.29 | X14: 0.076482935 | Y14: 0 | Z14: 0.48032514 | AA14: 3187800 | AB14: 863362.5 | AC14: 3187800 | AD14: =AC14-AC13 | AE14: 3187800
A15: 46012 | C15: 6641250 | D15: 4811400 | E15: 1848 | F15: 188.125 | G15: =F15+G14 | H15: 0.58 | I15: 2467746.1 | J15: 755.6 | K15: 1826.4175 | L15: -0.00095396701 | M15: =H15*C15 | N15: 1741321.6 | O15: 4209067.7 | P15: 1.1431035 | Q15: 602332.33 | R15: 0.090695626 | T15: 2432182.3 | U15: 0.27552795 | V15: 0.36622358 | W15: 602332.33 | X15: 0.090695626 | Y15: 931607.14 | Z15: 0.5862928 | AA15: 3851925 | AB15: 664125 | AC15: 2920317.9 | AD15: -267482.14 | AE15: 3851925
A16: 46043 | C16: 6641250 | D16: 4811400 | E16: 1848 | F16: 169.375 | G16: =F16+G15 | H16: 0.66 | I16: 2897830.7 | J16: 807.5 | K16: 2047.6875 | L16: 0.016813836 | M16: =H16*C16 | N16: 1886810.1 | O16: 4784640.9 | P16: 1.0055927 | Q16: 26759.136 | R16: 0.0040292319 | T16: 1856609.1 | U16: 0.27552795 | V16: 0.27955718 | W16: 26759.136 | X16: 0.0040292319 | Y16: 931607.14 | Z16: 0.60565272 | AA16: 4383225 | AB16: 531300 | AC16: 3451617.9 | AD16: 531300 | AE16: 4383225 | AF16: =AA19-AA15 | AG16: =AC19-AC15
A17: 46074 | C17: 6641250 | D17: 4811400 | E17: 1848 | F17: ='Current Effort - Consultation'!AJ31 | G17: =F17+G16 | H17: 0.62 | I17: 3483382.2 | J17: 849 | K17: 2205 | L17: 0.18349393 | M17: =H17*C17 | N17: 2180967.2 | O17: 5664349.3 | P17: 0.84941795 | Q17: -852949.35 | R17: -0.12843205 | T17: 976900.65 | U17: 0.27552795 | V17: 0.1470959 | W17: -852949.35 | X17: -0.12843205 | Y17: 1863214.3 | Z17: 0.61496599 | AA17: 4117575 | AB17: -265650 | AC17: 2254360.7 | AD17: -1197257.1 | AE17: 4117575
A18: 46102 | C18: 6641250 | D18: 4811400 | E18: 1848 | F18: ='Current Effort - Consultation'!AM31 | G18: 1538.38 | H18: 0.66 | I18: 3903237 | J18: 771.5 | K18: =J18+G18 | L18: =(G18/E18)/H18-100% | M18: =H18*C18 | N18: 1954833.7 | O18: =N18+I18 | P18: =D18/O18 | Q18: ='Budget - Consultation'!$I$15-O18 | R18: =Q18/'Budget - Consultation'!$I$16 | T18: ='Budget - Consultation'!$I$16-O18 | U18: 0.27552795 | V18: =T18/'Budget - Consultation'!$I$16 | W18: =T18-'Budget - Consultation'!$I$17 | X18: =V18-'Budget - Consultation'!$I$18 | Y18: 1863214.3 | Z18: 0.66599924 | AA18: 4383225 | AB18: =AA18-AA17 | AC18: 2520010.7 | AD18: =AC18-AC17 | AE18: 4383225 | AF18: =AC19-AC15 | AG18: =AA19-AA15
A19: 46133 | C19: 6641250 | D19: 4811400 | E19: 1848 | F19: ='Current Effort - Consultation'!AP31 | G19: ='Current Effort - Consultation'!AR31 | H19: 0.69 | I19: ='Current Effort - Consultation'!N34 | K19: =J19+G19 | L19: =(G19/E19)/H19-100% | M19: =H19*C19 | N19: =J19*'Current Effort - Consultation'!$N$35 | O19: =N19+I19 | P19: =D19/O19 | Q19: ='Budget - Consultation'!$I$15-O19 | R19: =Q19/'Budget - Consultation'!$I$16 | T19: ='Budget - Consultation'!$I$16-O19 | U19: ='Budget - Consultation'!$E$19 | V19: =T19/'Budget - Consultation'!$I$16 | W19: =T19-'Budget - Consultation'!$I$17 | X19: =V19-'Budget - Consultation'!$I$18 | Y19: =931607.14+931607.14+1863214 | Z19: =I19/O19 | AA19: =C19*H19 | AB19: =AA19-AA18 | AC19: =AA19-Y19 | AD19: =AC19-AC18 | AE19: =AC19+Y19

Sheet Help
B2: How to use this Cost Sheet
B11: # | C11: Column | D11: Description
B12: 1 | C12: Total Mandays | D12: Total Project Mandays as per the estimation, proposal or contract
B13: 2 | C13: Total Estimated Cost ($) | D13: Estimated cost based on estimation (FP Projects) or No of resources (T&M projects) Generally, estimated cost = No of Mandays* Cost per Manday
B14: 3 | C14: Total Estimated Cost (SAR) | D14: Estimated Cost in SAR
B15: 4 | C15: Total Revenue | D15: Revenue as per contract
B16: 5 | C16: Budget Profit (SAR) | D16: Profit = Revenue - Estimated Cost
B17: 6 | C17: Budget Profit (%) | D17: Profit as a percentage of Revenue
B18: 7 | C18: Current Cost (SAR) | D18: Current Cost based on current team effort - according to rate per hour for every resource
B19: 8 | C19: Estimated Remaining (MD) | D19: Remaining mandays in the project based on baseline estimation (FPP) or contract (T&M)
B20: 9 | C20: Estimated Cost to Complete | D20: = Estimated Remaining Mandays * Cost per Manday
B21: 10 | C21: Estimate at Completion | D21: = Current Cost + Estimated Remaining
B22: 11 | C22: Variance | D22: = Total Estimated Cost - Estimate at Completion
... B30: 19 | C30: Total Recognised Revenue | D30: = progress% * Revenue According to actual effort done and progress of work, this is the amount of invoices I should issue, or the revenue I should receive.

Sheet Estimated Cost (2)
A1: Put planned resources for the project and their positions to calculate Cost per month
A2: Delivery Estimation
A3: Name | B3: Position | C3: Hour Rate ($) | D3: Actual Time (MH) | E3: Onsite Rate ($) | F3: Actual Time Onsite (MH) | G3: Total Cost | H3: Cost * Period | I3: MD
A4: Amr Elwitidi | B4: KSA- Sr Business Analyst | C4: =VLOOKUP(B:B,Positions!A:B,2,0) | D4: =22*8 | E4: =19+Table_6710[[#This Row],[Hour Rate ($)]] | G4: =D4*C4+Table_6710[[#This Row],[Onsite Rate ($)]]*Table_6710[[#This Row],[Actual Time Onsite (MH)]] | H4: =Table_6710[[#This Row],[Total Cost]]*8 | I4: =(Table_6710[[#This Row],[Actual Time (MH)]]*8)/8
A5: Asmaa Ibrahim | B5: EGY - Sr Business Analyst | C5: =VLOOKUP(B:B,Positions!A:B,2,0) | D5: =22*8 | E5: =19+Table_6710[[#This Row],[Hour Rate ($)]] | G5: =D5*C5+Table_6710[[#This Row],[Onsite Rate ($)]]*Table_6710[[#This Row],[Actual Time Onsite (MH)]] | H5: =Table_6710[[#This Row],[Total Cost]]*4 | I5: =(Table_6710[[#This Row],[Actual Time (MH)]]*4)/8
A6: Mohamed Abdallah | B6: KSA - Project Manager | C6: =VLOOKUP(B:B,Positions!A:B,2,0) | D6: =22*8 | E6: =19+Table_6710[[#This Row],[Hour Rate ($)]] | G6: =D6*C6+Table_6710[[#This Row],[Onsite Rate ($)]]*Table_6710[[#This Row],[Actual Time Onsite (MH)]] | H6: =Table_6710[[#This Row],[Total Cost]]*9 | I6: =(Table_6710[[#This Row],[Actual Time (MH)]]*9)/8
A7: Abdessalem Hadad | B7: KSA - Solution Architect | C7: =VLOOKUP(B:B,Positions!A:B,2,0) | D7: =22*8 | E7: =19+Table_6710[[#This Row],[Hour Rate ($)]] | G7: =D7*C7+Table_6710[[#This Row],[Onsite Rate ($)]]*Table_6710[[#This Row],[Actual Time Onsite (MH)]] | H7: =Table_6710[[#This Row],[Total Cost]] | I7: =(Table_6710[[#This Row],[Actual Time (MH)]])/8
A8: Ahmed Serag | B8: KSA - Lead Software Engineer | C8: =VLOOKUP(B:B,Positions!A:B,2,0) | D8: =22*8 | E8: =19+Table_6710[[#This Row],[Hour Rate ($)]] | G8: =D8*C8+Table_6710[[#This Row],[Onsite Rate ($)]]*Table_6710[[#This Row],[Actual Time Onsite (MH)]] | H8: =Table_6710[[#This Row],[Total Cost]]*8 | I8: =(Table_6710[[#This Row],[Actual Time (MH)]]*8)/8
A9: Samah El Sayed | B9: KSA - Lead Software Engineer | C9: =VLOOKUP(B:B,Positions!A:B,2,0) | D9: =22*8 | E9: =19+Table_6710[[#This Row],[Hour Rate ($)]] | G9: =D9*C9+Table_6710[[#This Row],[Onsite Rate ($)]]*Table_6710[[#This Row],[Actual Time Onsite (MH)]] | H9: =Table_6710[[#This Row],[Total Cost]]*7 | I9: =(Table_6710[[#This Row],[Actual Time (MH)]]*7)/8
A10: Aya Saeed | B10: EGY - Sr. Software Engineer | C10: =VLOOKUP(B:B,Positions!A:B,2,0) | D10: =22*8 | E10: =19+Table_6710[[#This Row],[Hour Rate ($)]] | G10: =D10*C10+Table_6710[[#This Row],[Onsite Rate ($)]]*Table_6710[[#This Row],[Actual Time Onsite (MH)]] | H10: =Table_6710[[#This Row],[Total Cost]]*7 | I10: =(Table_6710[[#This Row],[Actual Time (MH)]]*7)/8
A11: Abdulrahman Abdallah | B11: EGY - Sr. Software Engineer | C11: =VLOOKUP(B:B,Positions!A:B,2,0) | D11: =22*8 | E11: =19+Table_6710[[#This Row],[Hour Rate ($)]] | G11: =D11*C11+Table_6710[[#This Row],[Onsite Rate ($)]]*Table_6710[[#This Row],[Actual Time Onsite (MH)]] | H11: =Table_6710[[#This Row],[Total Cost]]*8 | I11: =(Table_6710[[#This Row],[Actual Time (MH)]]*8)/8
A12: Senior Software Developer | B12: EGY - Sr. Software Engineer | C12: =VLOOKUP(B:B,Positions!A:B,2,0) | D12: =22*8 | E12: =19+Table_6710[[#This Row],[Hour Rate ($)]] | G12: =D12*C12+Table_6710[[#This Row],[Onsite Rate ($)]]*Table_6710[[#This Row],[Actual Time Onsite (MH)]] | H12: =Table_6710[[#This Row],[Total Cost]]*6 | I12: =(Table_6710[[#This Row],[Actual Time (MH)]]*6)/8
A13: Ahmed Gameel | B13: EGY - Software Engineer | C13: =VLOOKUP(B:B,Positions!A:B,2,0) | D13: =22*8 | E13: =19+Table_6710[[#This Row],[Hour Rate ($)]] | G13: =D13*C13+Table_6710[[#This Row],[Onsite Rate ($)]]*Table_6710[[#This Row],[Actual Time Onsite (MH)]] | H13: =Table_6710[[#This Row],[Total Cost]]*7 | I13: =(Table_6710[[#This Row],[Actual Time (MH)]]*7)/8
A14: Mahmoud Sayed | B14: EGY - Software Engineer | C14: =VLOOKUP(B:B,Positions!A:B,2,0) | D14: =22*8 | E14: =19+Table_6710[[#This Row],[Hour Rate ($)]] | G14: =D14*C14+Table_6710[[#This Row],[Onsite Rate ($)]]*Table_6710[[#This Row],[Actual Time Onsite (MH)]] | H14: =Table_6710[[#This Row],[Total Cost]]*5 | I14: =(Table_6710[[#This Row],[Actual Time (MH)]]*5)/8
A15: Fady Ayman | B15: EGY - Software Engineer | C15: =VLOOKUP(B:B,Positions!A:B,2,0) | D15: 176 | E15: =19+Table_6710[[#This Row],[Hour Rate ($)]] | G15: =D15*C15+Table_6710[[#This Row],[Onsite Rate ($)]]*Table_6710[[#This Row],[Actual Time Onsite (MH)]] | H15: =Table_6710[[#This Row],[Total Cost]]*4 | I15: =(Table_6710[[#This Row],[Actual Time (MH)]]*6)/8
A16: Rana Wael | B16: EGY - Software Engineer | C16: =VLOOKUP(B:B,Positions!A:B,2,0) | D16: =22*8 | E16: =19+Table_6710[[#This Row],[Hour Rate ($)]] | G16: =D16*C16+Table_6710[[#This Row],[Onsite Rate ($)]]*Table_6710[[#This Row],[Actual Time Onsite (MH)]] | H16: =Table_6710[[#This Row],[Total Cost]]*6 | I16: =(Table_6710[[#This Row],[Actual Time (MH)]]*4)/8
A17: Youmna Mahmoud | B17: EGY - Sr Quality Engineer | C17: =VLOOKUP(B:B,Positions!A:B,2,0) | D17: =22*8 | E17: =19+Table_6710[[#This Row],[Hour Rate ($)]] | G17: =D17*C17+Table_6710[[#This Row],[Onsite Rate ($)]]*Table_6710[[#This Row],[Actual Time Onsite (MH)]] | H17: =Table_6710[[#This Row],[Total Cost]]*8 | I17: =(Table_6710[[#This Row],[Actual Time (MH)]]*8)/8
A18: Yasmin Tarek | B18: EGY - Quality Engineer | C18: =VLOOKUP(B:B,Positions!A:B,2,0) | D18: =22*8 | E18: =19+Table_6710[[#This Row],[Hour Rate ($)]] | G18: =D18*C18+Table_6710[[#This Row],[Onsite Rate ($)]]*Table_6710[[#This Row],[Actual Time Onsite (MH)]] | H18: =Table_6710[[#This Row],[Total Cost]]*7 | I18: =(Table_6710[[#This Row],[Actual Time (MH)]]*7)/8
A19: Ahmed Badawy | B19: EGY - Quality Engineer | C19: =VLOOKUP(B:B,Positions!A:B,2,0) | D19: =22*8 | E19: =19+Table_6710[[#This Row],[Hour Rate ($)]] | G19: =D19*C19+Table_6710[[#This Row],[Onsite Rate ($)]]*Table_6710[[#This Row],[Actual Time Onsite (MH)]] | H19: =Table_6710[[#This Row],[Total Cost]]*7 | I19: =(Table_6710[[#This Row],[Actual Time (MH)]]*7)/8
A20: Mohamed Degwy | B20: EGY - Sr UX Designer | C20: =VLOOKUP(B:B,Positions!A:B,2,0) | D20: =22*8 | E20: =19+Table_6710[[#This Row],[Hour Rate ($)]] | G20: =D20*C20+Table_6710[[#This Row],[Onsite Rate ($)]]*Table_6710[[#This Row],[Actual Time Onsite (MH)]] | H20: =Table_6710[[#This Row],[Total Cost]]*2 | I20: =(Table_6710[[#This Row],[Actual Time (MH)]]*2)/8
A21: Menna Adel | B21: EGY - UX Designer | C21: =VLOOKUP(B:B,Positions!A:B,2,0) | D21: 176 | E21: =19+Table_6710[[#This Row],[Hour Rate ($)]] | G21: =D21*C21+Table_6710[[#This Row],[Onsite Rate ($)]]*Table_6710[[#This Row],[Actual Time Onsite (MH)]] | H21: =Table_6710[[#This Row],[Total Cost]]*3 | I21: =(Table_6710[[#This Row],[Actual Time (MH)]]*4)/8
A22: UI DESIGNER | B22: EGY - Sr UX Designer | C22: =VLOOKUP(B:B,Positions!A:B,2,0) | D22: =22*8 | E22: =19+Table_6710[[#This Row],[Hour Rate ($)]] | G22: =D22*C22+Table_6710[[#This Row],[Onsite Rate ($)]]*Table_6710[[#This Row],[Actual Time Onsite (MH)]] | H22: =Table_6710[[#This Row],[Total Cost]]*6 | I22: =(Table_6710[[#This Row],[Actual Time (MH)]]*6)/8
I23: =SUBTOTAL(109,Table_6710[MD])
A24: Fill in below info from Contract:
D25: TOTAL USD | G25: =SUM(H4:H22)
A26: Contract Period in months | D26: TOTAL Estimated Cost SAR | G26: =G25*3.75
A27: No of Resources required
A28: Total Mandays estimated for the project
A32: Support Estimation
A33: Name | B33: Position | C33: Hour Rate ($) | D33: Actual Time (MH) | E33: Onsite Rate ($) | F33: Actual Time Onsite (MH) | G33: Total Cost | H33: MD
A37: Fill in below info from Contract:
D38: TOTAL USD per month (22 days) | G38: =SUM(G34:G35)
A39: Contract Period in months | B39: 0 | D39: TOTAL Estimated Cost per month (22 days) SAR | G39: =G38*3.75
A40: No of Resources required | B40: =COUNTA(Table_67811[Name]) | D40: TOTAL Estimated Cost per Day SAR | G40: =G39/22
A41: Total Mandays estimated for the project | B41: =B39*22*B40 | D41: Cost for 7 months | G41: =G39*34

Sheet Estimated Cost - Development
A6: Position | B6: Hour Rate ($) | C6: Actual Time (MH) | D6: Cost per month | E6: Estimated # of Months | F6: Total cost USD | G6: Total No of MDs | H6: Column1
A7: KSA - Project Manager | B7: =VLOOKUP(A:A,[1]Positions2024!A:B,2,0) | C7: 176 | D7: =[1]!Table_67124[[#This Row],[Hour Rate ($)]]*[1]!Table_67124[[#This Row],[Actual Time (MH)]] | E7: 16 | F7: =[1]!Table_67124[[#This Row],[Estimated '# of Months]]*[1]!Table_67124[[#This Row],[Cost per month]] | G7: =([1]!Table_67124[[#This Row],[Actual Time (MH)]])*[1]!Table_67124[[#This Row],[Estimated '# of Months]]/8 | H7: =[1]!Table_67124[[#This Row],[Total cost USD]]*3.75
A8: EGY - Lead Software Engineer | B8: =VLOOKUP(A:A,[1]Positions2024!A:B,2,0) | C8: 176 | D8: =[1]!Table_67124[[#This Row],[Hour Rate ($)]]*[1]!Table_67124[[#This Row],[Actual Time (MH)]] | E8: 16 | F8: =[1]!Table_67124[[#This Row],[Estimated '# of Months]]*[1]!Table_67124[[#This Row],[Cost per month]] | G8: =([1]!Table_67124[[#This Row],[Actual Time (MH)]])*[1]!Table_67124[[#This Row],[Estimated '# of Months]]/8 | H8: =[1]!Table_67124[[#This Row],[Total cost USD]]*3.75
A9: KSA - Lead Software Engineer | B9: =VLOOKUP(A:A,[1]Positions2024!A:B,2,0) | C9: 176 | D9: =[1]!Table_67124[[#This Row],[Hour Rate ($)]]*[1]!Table_67124[[#This Row],[Actual Time (MH)]] | E9: 16 | F9: =[1]!Table_67124[[#This Row],[Estimated '# of Months]]*[1]!Table_67124[[#This Row],[Cost per month]] | G9: =([1]!Table_67124[[#This Row],[Actual Time (MH)]])*[1]!Table_67124[[#This Row],[Estimated '# of Months]]/8 | H9: =[1]!Table_67124[[#This Row],[Total cost USD]]*3.75
A10: KSA - Sr. Software Engineer | B10: =VLOOKUP(A:A,[1]Positions2024!A:B,2,0) | C10: 176 | D10: =[1]!Table_67124[[#This Row],[Hour Rate ($)]]*[1]!Table_67124[[#This Row],[Actual Time (MH)]] | E10: 16 | F10: =[1]!Table_67124[[#This Row],[Estimated '# of Months]]*[1]!Table_67124[[#This Row],[Cost per month]] | G10: =([1]!Table_67124[[#This Row],[Actual Time (MH)]])*[1]!Table_67124[[#This Row],[Estimated '# of Months]]/8 | H10: =[1]!Table_67124[[#This Row],[Total cost USD]]*3.75
A11: KSA - Sr. Software Engineer | B11: =VLOOKUP(A:A,[1]Positions2024!A:B,2,0) | C11: 176 | D11: =[1]!Table_67124[[#This Row],[Hour Rate ($)]]*[1]!Table_67124[[#This Row],[Actual Time (MH)]] | E11: 16 | F11: =[1]!Table_67124[[#This Row],[Estimated '# of Months]]*[1]!Table_67124[[#This Row],[Cost per month]] | G11: =([1]!Table_67124[[#This Row],[Actual Time (MH)]])*[1]!Table_67124[[#This Row],[Estimated '# of Months]]/8 | H11: =[1]!Table_67124[[#This Row],[Total cost USD]]*3.75
A12: KSA - Software Engineer | B12: =VLOOKUP(A:A,[1]Positions2024!A:B,2,0) | C12: 176 | D12: =[1]!Table_67124[[#This Row],[Hour Rate ($)]]*[1]!Table_67124[[#This Row],[Actual Time (MH)]] | E12: 16 | F12: =[1]!Table_67124[[#This Row],[Estimated '# of Months]]*[1]!Table_67124[[#This Row],[Cost per month]] | G12: =([1]!Table_67124[[#This Row],[Actual Time (MH)]])*[1]!Table_67124[[#This Row],[Estimated '# of Months]]/8 | H12: =[1]!Table_67124[[#This Row],[Total cost USD]]*3.75
A13: EGY - Sr. Software Engineer | B13: =VLOOKUP(A:A,[1]Positions2024!A:B,2,0) | C13: 176 | D13: =[1]!Table_67124[[#This Row],[Hour Rate ($)]]*[1]!Table_67124[[#This Row],[Actual Time (MH)]] | E13: 16 | F13: =[1]!Table_67124[[#This Row],[Estimated '# of Months]]*[1]!Table_67124[[#This Row],[Cost per month]] | G13: =([1]!Table_67124[[#This Row],[Actual Time (MH)]])*[1]!Table_67124[[#This Row],[Estimated '# of Months]]/8 | H13: =[1]!Table_67124[[#This Row],[Total cost USD]]*3.75
A14: EGY - Sr. Software Engineer | B14: =VLOOKUP(A:A,[1]Positions2024!A:B,2,0) | C14: 176 | D14: =[1]!Table_67124[[#This Row],[Hour Rate ($)]]*[1]!Table_67124[[#This Row],[Actual Time (MH)]] | E14: 16 | F14: =[1]!Table_67124[[#This Row],[Estimated '# of Months]]*[1]!Table_67124[[#This Row],[Cost per month]] | G14: =([1]!Table_67124[[#This Row],[Actual Time (MH)]])*[1]!Table_67124[[#This Row],[Estimated '# of Months]]/8 | H14: =[1]!Table_67124[[#This Row],[Total cost USD]]*3.75
A15: EGY - Software Engineer | B15: =VLOOKUP(A:A,[1]Positions2024!A:B,2,0) | C15: 176 | D15: =[1]!Table_67124[[#This Row],[Hour Rate ($)]]*[1]!Table_67124[[#This Row],[Actual Time (MH)]] | E15: 16 | F15: =[1]!Table_67124[[#This Row],[Estimated '# of Months]]*[1]!Table_67124[[#This Row],[Cost per month]] | G15: =([1]!Table_67124[[#This Row],[Actual Time (MH)]])*[1]!Table_67124[[#This Row],[Estimated '# of Months]]/8 | H15: =[1]!Table_67124[[#This Row],[Total cost USD]]*3.75
A16: EGY - Software Engineer | B16: =VLOOKUP(A:A,[1]Positions2024!A:B,2,0) | C16: 176 | D16: =[1]!Table_67124[[#This Row],[Hour Rate ($)]]*[1]!Table_67124[[#This Row],[Actual Time (MH)]] | E16: 16 | F16: =[1]!Table_67124[[#This Row],[Estimated '# of Months]]*[1]!Table_67124[[#This Row],[Cost per month]] | G16: =([1]!Table_67124[[#This Row],[Actual Time (MH)]])*[1]!Table_67124[[#This Row],[Estimated '# of Months]]/8 | H16: =[1]!Table_67124[[#This Row],[Total cost USD]]*3.75
A17: EGY - Software Engineer | B17: =VLOOKUP(A:A,[1]Positions2024!A:B,2,0) | C17: 176 | D17: =[1]!Table_67124[[#This Row],[Hour Rate ($)]]*[1]!Table_67124[[#This Row],[Actual Time (MH)]] | E17: 16 | F17: =[1]!Table_67124[[#This Row],[Estimated '# of Months]]*[1]!Table_67124[[#This Row],[Cost per month]] | G17: =([1]!Table_67124[[#This Row],[Actual Time (MH)]])*[1]!Table_67124[[#This Row],[Estimated '# of Months]]/8 | H17: =[1]!Table_67124[[#This Row],[Total cost USD]]*3.75
A18: EGY - Software Engineer | B18: =VLOOKUP(A:A,[1]Positions2024!A:B,2,0) | C18: 176 | D18: =[1]!Table_67124[[#This Row],[Hour Rate ($)]]*[1]!Table_67124[[#This Row],[Actual Time (MH)]] | E18: 16 | F18: =[1]!Table_67124[[#This Row],[Estimated '# of Months]]*[1]!Table_67124[[#This Row],[Cost per month]] | G18: =([1]!Table_67124[[#This Row],[Actual Time (MH)]])*[1]!Table_67124[[#This Row],[Estimated '# of Months]]/8 | H18: =[1]!Table_67124[[#This Row],[Total cost USD]]*3.75
... A26: KSA - Sr. Software Engineer | B26: =VLOOKUP(A:A,[1]Positions2024!A:B,2,0) | C26: 176 | D26: =[1]!Table_67124[[#This Row],[Hour Rate ($)]]*[1]!Table_67124[[#This Row],[Actual Time (MH)]] | E26: 12 | F26: =[1]!Table_67124[[#This Row],[Estimated '# of Months]]*[1]!Table_67124[[#This Row],[Cost per month]] | G26: =([1]!Table_67124[[#This Row],[Actual Time (MH)]])*[1]!Table_67124[[#This Row],[Estimated '# of Months]]/8 | H26: =[1]!Table_67124[[#This Row],[Total cost USD]]*3.75
F27: =SUM(Table_67124[Total cost USD]) | G27: =SUBTOTAL(109,Table_67124[Total No of MDs])
C29: TOTAL USD per month (22 days) | D29: =SUM(D7:D26)
C30: TOTAL Estimated Cost per month (22 days) SAR | D30: =D29*3.75
C31: Estimated MDs / Month | D31: =(SUM(Table_67124[Actual Time (MH)]))/8
C32: TOTAL Estimated Cost per MD SAR | D32: =D30/D31
C33: Total project estimated Cost (SAR) | D33: =Table_67124[[#Totals],[Total cost USD]]*3.75

Sheet Estimated Cost - Consultation
A6: Position | B6: Hour Rate ($) | C6: Actual Time (MH) | D6: Cost per month | E6: Estimated # of Months | F6: Total cost USD | G6: Total No of MDs | H6: Column1
A7: KSA - Solution Architect / Manager | B7: =VLOOKUP(A:A,Positions2024!A:B,2,0) | C7: 176 | D7: =Table_6712[[#This Row],[Hour Rate ($)]]*Table_6712[[#This Row],[Actual Time (MH)]] | E7: 12 | F7: =Table_6712[[#This Row],[Estimated '# of Months]]*Table_6712[[#This Row],[Cost per month]] | G7: =(Table_6712[[#This Row],[Actual Time (MH)]])*Table_6712[[#This Row],[Estimated '# of Months]]/8 | H7: =Table_6712[[#This Row],[Total cost USD]]*3.75
A8: KSA - Solution Architect / Manager | B8: =VLOOKUP(A:A,Positions2024!A:B,2,0) | C8: 176 | D8: =Table_6712[[#This Row],[Hour Rate ($)]]*Table_6712[[#This Row],[Actual Time (MH)]] | E8: 3 | F8: =Table_6712[[#This Row],[Estimated '# of Months]]*Table_6712[[#This Row],[Cost per month]] | G8: =(Table_6712[[#This Row],[Actual Time (MH)]])*Table_6712[[#This Row],[Estimated '# of Months]]/8 | H8: =Table_6712[[#This Row],[Total cost USD]]*3.75
A9: KSA - Solution Architect / Manager | B9: =VLOOKUP(A:A,Positions2024!A:B,2,0) | C9: 176 | D9: =Table_6712[[#This Row],[Hour Rate ($)]]*Table_6712[[#This Row],[Actual Time (MH)]] | E9: 3 | F9: =Table_6712[[#This Row],[Estimated '# of Months]]*Table_6712[[#This Row],[Cost per month]] | G9: =(Table_6712[[#This Row],[Actual Time (MH)]])*Table_6712[[#This Row],[Estimated '# of Months]]/8 | H9: =Table_6712[[#This Row],[Total cost USD]]*3.75
A10: KSA - Solution Architect / Manager | B10: =VLOOKUP(A:A,Positions2024!A:B,2,0) | C10: 176 | D10: =Table_6712[[#This Row],[Hour Rate ($)]]*Table_6712[[#This Row],[Actual Time (MH)]] | E10: 3 | F10: =Table_6712[[#This Row],[Estimated '# of Months]]*Table_6712[[#This Row],[Cost per month]] | G10: =(Table_6712[[#This Row],[Actual Time (MH)]])*Table_6712[[#This Row],[Estimated '# of Months]]/8 | H10: =Table_6712[[#This Row],[Total cost USD]]*3.75
A11: KSA - Solution Architect / Manager | B11: =VLOOKUP(A:A,Positions2024!A:B,2,0) | C11: 176 | D11: =Table_6712[[#This Row],[Hour Rate ($)]]*Table_6712[[#This Row],[Actual Time (MH)]] | E11: 3 | F11: =Table_6712[[#This Row],[Estimated '# of Months]]*Table_6712[[#This Row],[Cost per month]] | G11: =(Table_6712[[#This Row],[Actual Time (MH)]])*Table_6712[[#This Row],[Estimated '# of Months]]/8 | H11: =Table_6712[[#This Row],[Total cost USD]]*3.75
A12: KSA - Solution Architect / Manager | B12: =VLOOKUP(A:A,Positions2024!A:B,2,0) | C12: 176 | D12: =Table_6712[[#This Row],[Hour Rate ($)]]*Table_6712[[#This Row],[Actual Time (MH)]] | E12: 12 | F12: =Table_6712[[#This Row],[Estimated '# of Months]]*Table_6712[[#This Row],[Cost per month]] | G12: =(Table_6712[[#This Row],[Actual Time (MH)]])*Table_6712[[#This Row],[Estimated '# of Months]]/8 | H12: =Table_6712[[#This Row],[Total cost USD]]*3.75
A13: KSA- Sr Business Analyst | B13: =VLOOKUP(A:A,Positions2024!A:B,2,0) | C13: 176 | D13: =Table_6712[[#This Row],[Hour Rate ($)]]*Table_6712[[#This Row],[Actual Time (MH)]] | E13: 12 | F13: =Table_6712[[#This Row],[Estimated '# of Months]]*Table_6712[[#This Row],[Cost per month]] | G13: =(Table_6712[[#This Row],[Actual Time (MH)]])*Table_6712[[#This Row],[Estimated '# of Months]]/8 | H13: =Table_6712[[#This Row],[Total cost USD]]*3.75
